{
    "created": 1717039707.2632875,
    "duration": 0.17008399963378906,
    "exitcode": 4,
    "root": "D:\\1\\shuke_api_autotest",
    "environment": {
        "Python": "3.12.2",
        "Platform": "Windows-11-10.0.22631-SP0",
        "Packages": {
            "pytest": "6.2.5",
            "py": "1.11.0",
            "pluggy": "1.5.0"
        },
        "Plugins": {
            "allure-pytest": "2.8.13",
            "forked": "1.6.0",
            "html": "2.1.1",
            "json-report": "1.2.1",
            "metadata": "1.8.0",
            "ordering": "0.6",
            "rerunfailures": "10.1",
            "xdist": "2.5.0"
        },
        "JAVA_HOME": "C:\\Program Files\\Java\\jdk-21"
    },
    "summary": {
        "total": 0,
        "collected": 0
    },
    "collectors": [
        {
            "nodeid": "dianxiao_api_autotest/fundmanage/testcases/test_task.py",
            "outcome": "failed",
            "result": [],
            "longrepr": "ImportError while importing test module 'D:\\1\\shuke_api_autotest\\dianxiao_api_autotest\\fundmanage\\testcases\\test_task.py'.\nHint: make sure your test modules/packages have valid Python names.\nTraceback:\nD:\\shuke_api_autotest\\venv\\Lib\\site-packages\\requests_toolbelt\\_compat.py:48: in <module>\n    from requests.packages.urllib3.contrib import appengine as gaecontrib\nE   ImportError: cannot import name 'appengine' from 'urllib3.contrib' (D:\\shuke_api_autotest\\venv\\Lib\\site-packages\\urllib3\\contrib\\__init__.py)\n\nDuring handling of the above exception, another exception occurred:\nD:\\shuke_api_autotest\\venv\\Lib\\site-packages\\_pytest\\python.py:578: in _importtestmodule\n    mod = import_path(self.fspath, mode=importmode)\nD:\\shuke_api_autotest\\venv\\Lib\\site-packages\\_pytest\\pathlib.py:524: in import_path\n    importlib.import_module(module_name)\nC:\\Users\\wanghouxuan-jk\\AppData\\Local\\Programs\\Python\\Python312\\Lib\\importlib\\__init__.py:90: in import_module\n    return _bootstrap._gcd_import(name[level:], package, level)\n<frozen importlib._bootstrap>:1387: in _gcd_import\n    ???\n<frozen importlib._bootstrap>:1360: in _find_and_load\n    ???\n<frozen importlib._bootstrap>:1331: in _find_and_load_unlocked\n    ???\n<frozen importlib._bootstrap>:935: in _load_unlocked\n    ???\nD:\\shuke_api_autotest\\venv\\Lib\\site-packages\\_pytest\\assertion\\rewrite.py:170: in exec_module\n    exec(co, module.__dict__)\ntest_task.py:4: in <module>\n    from dianxiao_api_autotest.fundmanage.services.task_service import Task\n..\\services\\task_service.py:3: in <module>\n    from requests_toolbelt.multipart.encoder import MultipartEncoder\nD:\\shuke_api_autotest\\venv\\Lib\\site-packages\\requests_toolbelt\\__init__.py:12: in <module>\n    from .adapters import SSLAdapter, SourceAddressAdapter\nD:\\shuke_api_autotest\\venv\\Lib\\site-packages\\requests_toolbelt\\adapters\\__init__.py:12: in <module>\n    from .ssl import SSLAdapter\nD:\\shuke_api_autotest\\venv\\Lib\\site-packages\\requests_toolbelt\\adapters\\ssl.py:16: in <module>\n    from .._compat import poolmanager\nD:\\shuke_api_autotest\\venv\\Lib\\site-packages\\requests_toolbelt\\_compat.py:50: in <module>\n    from urllib3.contrib import appengine as gaecontrib\nE   ImportError: cannot import name 'appengine' from 'urllib3.contrib' (D:\\shuke_api_autotest\\venv\\Lib\\site-packages\\urllib3\\contrib\\__init__.py)"
        },
        {
            "nodeid": "",
            "outcome": "passed",
            "result": []
        }
    ],
    "tests": [],
    "warnings": [
        {
            "message": "urllib3 (2.2.1) or chardet (3.0.4) doesn't match a supported version!",
            "category": "RequestsDependencyWarning",
            "when": "config",
            "filename": "D:\\shuke_api_autotest\\venv\\Lib\\site-packages\\requests\\__init__.py",
            "lineno": 89
        },
        {
            "message": "Unknown config option: pythonpath\n",
            "category": "PytestConfigWarning",
            "when": "config",
            "filename": "D:\\shuke_api_autotest\\venv\\Lib\\site-packages\\_pytest\\config\\__init__.py",
            "lineno": 1233
        }
    ]
}